<?xml version="1.0"?>
<robot name="custum_robot">
    <!-- Outside world-->
    <link name="world" />
    <!-- Base of the robot -->
    <link name="base_link" />

    <joint name="base_joint" type="fixed">
        <origin xyz="0 0 0" rpy="0 0 0" />
        <axis xyz="1 0 0"/>
        <parent link="world"/>
        <child link="base_link"/>
    </joint>

    <!-- Add a continuosly rotating joint connecting the 
    fixed base to the moveable link -->

    <joint name="joint1" type="continuous">
        <origin xyz="0 0 0.5" rpy="0 0 0" />
        <axis xyz="1 0 0"/>
        <parent link="base_link"/>
        <child link="link1"/>
    </joint>

    <!-- Moveable link-->
    <link name="link1"/>
</robot>